2019-06-05 22:11:00,624 [INFO ]  Starting Rasa Core server on http://localhost:5005
2019-06-05 22:13:26,918 [INFO ]  Killing Sanic server now.
2019-06-05 22:13:49,088 [INFO ]  Starting Rasa Core server on http://localhost:5005
2019-06-05 22:15:57,419 [INFO ]  Killing Sanic server now.
2019-06-05 22:23:00,334 [INFO ]  Starting Rasa Core server on http://localhost:5005
2019-06-06 06:13:34,350 [INFO ]  Starting Rasa Core server on http://localhost:5005
2019-06-06 06:13:46,175 [ERROR]  Exception occurred while handling uri: 'http://localhost:5005/version'
Traceback (most recent call last):
  File "/usr/local/lib/python3.6/site-packages/sanic/app.py", line 893, in handle_request
    handler, args, kwargs, uri = self.router.get(request)
  File "/usr/local/lib/python3.6/site-packages/sanic/router.py", line 407, in get
    return self._get(request.path, request.method, "")
  File "/usr/local/lib/python3.6/site-packages/sanic/router.py", line 469, in _get
    raise NotFound("Requested URL {} not found".format(url))
sanic.exceptions.NotFound: Requested URL /version not found
2019-06-06 06:13:52,713 [ERROR]  Exception occurred while handling uri: 'http://localhost:5005/version'
Traceback (most recent call last):
  File "/usr/local/lib/python3.6/site-packages/sanic/app.py", line 893, in handle_request
    handler, args, kwargs, uri = self.router.get(request)
  File "/usr/local/lib/python3.6/site-packages/sanic/router.py", line 407, in get
    return self._get(request.path, request.method, "")
  File "/usr/local/lib/python3.6/site-packages/sanic/router.py", line 469, in _get
    raise NotFound("Requested URL {} not found".format(url))
sanic.exceptions.NotFound: Requested URL /version not found
2019-06-06 06:14:39,987 [ERROR]  Exception occurred while handling uri: 'http://localhost:5005/'
Traceback (most recent call last):
  File "/usr/local/lib/python3.6/site-packages/sanic/app.py", line 893, in handle_request
    handler, args, kwargs, uri = self.router.get(request)
  File "/usr/local/lib/python3.6/site-packages/sanic/router.py", line 407, in get
    return self._get(request.path, request.method, "")
  File "/usr/local/lib/python3.6/site-packages/sanic/router.py", line 469, in _get
    raise NotFound("Requested URL {} not found".format(url))
sanic.exceptions.NotFound: Requested URL / not found
2019-06-06 06:14:43,549 [ERROR]  Exception occurred while handling uri: 'http://localhost:5005/'
Traceback (most recent call last):
  File "/usr/local/lib/python3.6/site-packages/sanic/app.py", line 893, in handle_request
    handler, args, kwargs, uri = self.router.get(request)
  File "/usr/local/lib/python3.6/site-packages/sanic/router.py", line 407, in get
    return self._get(request.path, request.method, "")
  File "/usr/local/lib/python3.6/site-packages/sanic/router.py", line 469, in _get
    raise NotFound("Requested URL {} not found".format(url))
sanic.exceptions.NotFound: Requested URL / not found
2019-06-06 06:16:55,010 [ERROR]  Exception occurred while handling uri: 'http://localhost:5005/webhook'
Traceback (most recent call last):
  File "/usr/local/lib/python3.6/site-packages/sanic/app.py", line 893, in handle_request
    handler, args, kwargs, uri = self.router.get(request)
  File "/usr/local/lib/python3.6/site-packages/sanic/router.py", line 407, in get
    return self._get(request.path, request.method, "")
  File "/usr/local/lib/python3.6/site-packages/sanic/router.py", line 469, in _get
    raise NotFound("Requested URL {} not found".format(url))
sanic.exceptions.NotFound: Requested URL /webhook not found
2019-06-06 06:19:18,311 [ERROR]  Exception occurred while handling uri: 'http://localhost:5005/webhook/rest/webhook'
Traceback (most recent call last):
  File "/usr/local/lib/python3.6/site-packages/sanic/app.py", line 893, in handle_request
    handler, args, kwargs, uri = self.router.get(request)
  File "/usr/local/lib/python3.6/site-packages/sanic/router.py", line 407, in get
    return self._get(request.path, request.method, "")
  File "/usr/local/lib/python3.6/site-packages/sanic/router.py", line 469, in _get
    raise NotFound("Requested URL {} not found".format(url))
sanic.exceptions.NotFound: Requested URL /webhook/rest/webhook not found
2019-06-06 06:19:27,586 [ERROR]  Exception occurred while handling uri: 'http://localhost:5005/webhook/rest/webhook'
Traceback (most recent call last):
  File "/usr/local/lib/python3.6/site-packages/sanic/app.py", line 893, in handle_request
    handler, args, kwargs, uri = self.router.get(request)
  File "/usr/local/lib/python3.6/site-packages/sanic/router.py", line 407, in get
    return self._get(request.path, request.method, "")
  File "/usr/local/lib/python3.6/site-packages/sanic/router.py", line 469, in _get
    raise NotFound("Requested URL {} not found".format(url))
sanic.exceptions.NotFound: Requested URL /webhook/rest/webhook not found
2019-06-06 06:19:38,205 [ERROR]  Exception occurred while handling uri: 'http://localhost:5005/'
Traceback (most recent call last):
  File "/usr/local/lib/python3.6/site-packages/sanic/app.py", line 893, in handle_request
    handler, args, kwargs, uri = self.router.get(request)
  File "/usr/local/lib/python3.6/site-packages/sanic/router.py", line 407, in get
    return self._get(request.path, request.method, "")
  File "/usr/local/lib/python3.6/site-packages/sanic/router.py", line 469, in _get
    raise NotFound("Requested URL {} not found".format(url))
sanic.exceptions.NotFound: Requested URL / not found
2019-06-06 06:23:33,515 [ERROR]  Exception occurred while handling uri: 'http://localhost:5005/conversations/default/respond'
Traceback (most recent call last):
  File "/usr/local/lib/python3.6/site-packages/sanic/app.py", line 893, in handle_request
    handler, args, kwargs, uri = self.router.get(request)
  File "/usr/local/lib/python3.6/site-packages/sanic/router.py", line 407, in get
    return self._get(request.path, request.method, "")
  File "/usr/local/lib/python3.6/site-packages/sanic/router.py", line 469, in _get
    raise NotFound("Requested URL {} not found".format(url))
sanic.exceptions.NotFound: Requested URL /conversations/default/respond not found
2019-06-06 06:23:41,494 [ERROR]  Exception occurred while handling uri: 'http://localhost:5005/conversations/default/'
Traceback (most recent call last):
  File "/usr/local/lib/python3.6/site-packages/sanic/app.py", line 893, in handle_request
    handler, args, kwargs, uri = self.router.get(request)
  File "/usr/local/lib/python3.6/site-packages/sanic/router.py", line 407, in get
    return self._get(request.path, request.method, "")
  File "/usr/local/lib/python3.6/site-packages/sanic/router.py", line 469, in _get
    raise NotFound("Requested URL {} not found".format(url))
sanic.exceptions.NotFound: Requested URL /conversations/default/ not found
2019-06-06 06:23:45,355 [ERROR]  Exception occurred while handling uri: 'http://localhost:5005/conversations/default'
Traceback (most recent call last):
  File "/usr/local/lib/python3.6/site-packages/sanic/app.py", line 893, in handle_request
    handler, args, kwargs, uri = self.router.get(request)
  File "/usr/local/lib/python3.6/site-packages/sanic/router.py", line 407, in get
    return self._get(request.path, request.method, "")
  File "/usr/local/lib/python3.6/site-packages/sanic/router.py", line 469, in _get
    raise NotFound("Requested URL {} not found".format(url))
sanic.exceptions.NotFound: Requested URL /conversations/default not found
2019-06-06 06:27:52,319 [ERROR]  Exception occurred while handling uri: 'http://localhost:5005/api'
Traceback (most recent call last):
  File "/usr/local/lib/python3.6/site-packages/sanic/app.py", line 893, in handle_request
    handler, args, kwargs, uri = self.router.get(request)
  File "/usr/local/lib/python3.6/site-packages/sanic/router.py", line 407, in get
    return self._get(request.path, request.method, "")
  File "/usr/local/lib/python3.6/site-packages/sanic/router.py", line 469, in _get
    raise NotFound("Requested URL {} not found".format(url))
sanic.exceptions.NotFound: Requested URL /api not found
2019-06-06 06:41:07,833 [INFO ]  Starting Rasa Core server on http://localhost:5005
2019-06-06 06:42:10,140 [ERROR]  Exception occurred while handling uri: 'http://localhost:5005/'
Traceback (most recent call last):
  File "/usr/local/lib/python3.6/site-packages/sanic/app.py", line 893, in handle_request
    handler, args, kwargs, uri = self.router.get(request)
  File "/usr/local/lib/python3.6/site-packages/sanic/router.py", line 407, in get
    return self._get(request.path, request.method, "")
  File "/usr/local/lib/python3.6/site-packages/sanic/router.py", line 446, in _get
    raise method_not_supported
sanic.exceptions.MethodNotSupported: Method POST not allowed for URL /
2019-06-06 06:43:26,834 [ERROR]  An exception occured while handling user message 'None'.
Traceback (most recent call last):
  File "/usr/local/lib/python3.6/site-packages/rasa/core/channels/channel.py", line 447, in receive
    text, collector, sender_id, input_channel=self.name()
  File "/usr/local/lib/python3.6/site-packages/rasa/core/channels/channel.py", line 68, in handler
    await app.agent.handle_message(*args, **kwargs)
  File "/usr/local/lib/python3.6/site-packages/rasa/core/agent.py", line 441, in handle_message
    return await processor.handle_message(message)
  File "/usr/local/lib/python3.6/site-packages/rasa/core/processor.py", line 70, in handle_message
    tracker = await self.log_message(message)
  File "/usr/local/lib/python3.6/site-packages/rasa/core/processor.py", line 118, in log_message
    await self._handle_message_with_tracker(message, tracker)
  File "/usr/local/lib/python3.6/site-packages/rasa/core/processor.py", line 286, in _handle_message_with_tracker
    parse_data = await self._parse_message(message)
  File "/usr/local/lib/python3.6/site-packages/rasa/core/processor.py", line 264, in _parse_message
    if message.text.startswith(INTENT_MESSAGE_PREFIX):
AttributeError: 'NoneType' object has no attribute 'startswith'
2019-06-09 22:32:14,654 [INFO ]  Starting Rasa Core server on http://localhost:5005
2019-06-09 22:35:41,421 [INFO ]  Starting Rasa Core server on http://localhost:5005
2019-06-09 22:43:39,757 [INFO ]  Starting Rasa Core server on http://localhost:5005
2019-06-09 22:45:24,538 [INFO ]  Starting Rasa Core server on http://localhost:5005
2019-06-09 22:46:17,945 [INFO ]  Starting Rasa Core server on http://localhost:5005
2019-06-09 23:14:02,040 [ERROR]  Exception occurred while handling uri: 'http://rasa:5005/'
Traceback (most recent call last):
  File "/usr/local/lib/python3.6/site-packages/sanic/app.py", line 893, in handle_request
    handler, args, kwargs, uri = self.router.get(request)
  File "/usr/local/lib/python3.6/site-packages/sanic/router.py", line 407, in get
    return self._get(request.path, request.method, "")
  File "/usr/local/lib/python3.6/site-packages/sanic/router.py", line 469, in _get
    raise NotFound("Requested URL {} not found".format(url))
sanic.exceptions.NotFound: Requested URL / not found
2019-06-09 23:14:29,229 [ERROR]  Exception occurred while handling uri: 'http://rasa:5005/webhooks/rest/webhook'
Traceback (most recent call last):
  File "/usr/local/lib/python3.6/site-packages/sanic/app.py", line 893, in handle_request
    handler, args, kwargs, uri = self.router.get(request)
  File "/usr/local/lib/python3.6/site-packages/sanic/router.py", line 407, in get
    return self._get(request.path, request.method, "")
  File "/usr/local/lib/python3.6/site-packages/sanic/router.py", line 446, in _get
    raise method_not_supported
sanic.exceptions.MethodNotSupported: Method GET not allowed for URL /webhooks/rest/webhook
2019-06-09 23:50:23,153 [ERROR]  Exception occurred while handling uri: 'http://rasa.micado.it:5005/status'
Traceback (most recent call last):
  File "/usr/local/lib/python3.6/site-packages/sanic/app.py", line 893, in handle_request
    handler, args, kwargs, uri = self.router.get(request)
  File "/usr/local/lib/python3.6/site-packages/sanic/router.py", line 407, in get
    return self._get(request.path, request.method, "")
  File "/usr/local/lib/python3.6/site-packages/sanic/router.py", line 469, in _get
    raise NotFound("Requested URL {} not found".format(url))
sanic.exceptions.NotFound: Requested URL /status not found
2019-06-09 23:50:28,432 [ERROR]  Exception occurred while handling uri: 'http://rasa.micado.it:5005/status'
Traceback (most recent call last):
  File "/usr/local/lib/python3.6/site-packages/sanic/app.py", line 893, in handle_request
    handler, args, kwargs, uri = self.router.get(request)
  File "/usr/local/lib/python3.6/site-packages/sanic/router.py", line 407, in get
    return self._get(request.path, request.method, "")
  File "/usr/local/lib/python3.6/site-packages/sanic/router.py", line 469, in _get
    raise NotFound("Requested URL {} not found".format(url))
sanic.exceptions.NotFound: Requested URL /status not found
